Workbook

Sheet Java
A1: # | B1: Вопросы | C1: Баллы | D1: Длительность (мин) | E1: № старого вопроса | F1: Сложность | G1: Вступительное | H1: 1 | I1: 2 | J1: 3
B2: Архитектура современных приложений | C2: =SUM(C3:C8) -> 6 | D2: =SUM(D3:D8) -> 30 | O2: Зачтено
A3: A1 | B3: Консольные приложения | C3: 1 | D3: 5 | O3: В процессе
A4: A2 | B4: Архитектура клиент-сервер | C4: 3 | D4: 15 | G4: Зачтено
B5: Взаимодействие серверов с клиентами
B6: 2х, 3х и многоуровневая архитектура клиент-сервер
B7: Тонкий и толстый клиент
A8: A3 | B8: Web Services | C8: 2 | D8: 10 | H8: В процессе 4
B9: SOAP
B10: RESTful
B11: Сравнение, преимущества/недостатки
B13: ООП | C13: =SUM(C14,C20) -> 3 | D13: =SUM(D14:D20) -> 30
A14: O1 | B14: Основные понятия | C14: 1 | D14: 10 | G14: Зачтено
B15: Инкапсуляция
B16: Наследование
B17: Полиморфизм
B18: Типы взаимоотношений классов (ассоциация, агрегация и композиция, обобщение/расширение (наследование))
B19: Интерфейс, абстрактный класс
A20: O2 | B20: Основные паттерны ООП | C20: 2 | D20: 20 | H20: В процессе 4
B22: Программирование (Java) | C22: =SUM(C23:C199) -> 64 | D22: =SUM(D23:D203) -> 550
A23: J1 | B23: Основные понятия и типы данных | C23: 1 | D23: 10 | E23: J1 | F23: 1 | G23: Зачтено
B24: Объявление
B25: Области видимости (модификаторы доступа)
B26: Boxing и Unboxing
B27: Примитивные и Ссылочный типы
B28: Модель памяти. Сборка мусора GC
A29: J2 | B29: Знание синтаксиса и конструкций языка | C29: 1 | D29: 15 | E29: J3 | F29: 1 | G29: Зачтено
B30: Операторы
B31: Логические выражения
B32: Управляющие конструкции
B33: Интерфейсы, Классы, Абстрактные классы
B34: Внутренние и вложенные классы
B35: Ключевые слова static и final
B36: Enums
B37: Работы с пакетами
A38: J3 | B38: Коллекции (а так же хэшированные наборы данных) | C38: 1 | D38: 20 | E38: J2 | F38: 1 | G38: Зачтено
B39: Иерархия коллекций
B40: Iterable, Collection
B41: List и его реализации
B42: Set и его реализации
...

Sheet JS
A1: =Java!A1 -> # | B1: =Java!B1 -> Вопросы | C1: =Java!C1 -> Баллы | D1: =Java!D1 -> Длительность (мин) | E1: =Java!E1 -> № старого вопроса | F1: =Java!F1 -> Сложность
B2: =Java!B2 -> Архитектура современных приложений | C2: =Java!C2 -> 6 | D2: =Java!D2 -> 30
A3: =Java!A3 -> A1 | B3: =Java!B3 -> Консольные приложения | C3: =Java!C3 -> 1 | D3: =Java!D3 -> 5
A4: =Java!A4 -> A2 | B4: =Java!B4 -> Архитектура клиент-сервер | C4: =Java!C4 -> 3 | D4: =Java!D4 -> 15
B5: =Java!B5 -> Взаимодействие серверов с клиентами
B6: =Java!B6 -> 2х, 3х и многоуровневая архитектура клиент-сервер
B7: =Java!B7 -> Тонкий и толстый клиент
A8: =Java!A8 -> A3 | B8: =Java!B8 -> Web Services | C8: =Java!C8 -> 2 | D8: =Java!D8 -> 10
B9: =Java!B9 -> SOAP
B10: =Java!B10 -> RESTful
B11: =Java!B11 -> Сравнение, преимущества/недостатки
B13: =Java!B13 -> ООП | C13: =Java!C13 -> 3 | D13: =Java!D13 -> 30
A14: =Java!A14 -> O1 | B14: =Java!B14 -> Основные понятия | C14: =Java!C14 -> 1 | D14: =Java!D14 -> 10
B15: =Java!B15 -> Инкапсуляция
B16: =Java!B16 -> Наследование
B17: =Java!B17 -> Полиморфизм
B18: =Java!B18 -> Типы взаимоотношений классов (ассоциация, агрегация и композиция, обобщение/расширение (наследование))
B19: =Java!B19 -> Интерфейс, абстрактный класс
A20: =Java!A20 -> O2 | B20: =Java!B20 -> Основные паттерны ООП | C20: =Java!C20 -> 2 | D20: =Java!D20 -> 20
B22: Программирование (JS) | C22: =SUM(C23:C113) -> 62 | D22: =SUM(D23:D115) -> 550
A23: JS1 | B23: Базовые сведения | C23: 1 | D23: 15 | E23: JS1 | F23: 1
B24: Типы данных
B25: Операторы языка
B26: Циклы, управляющие конструкции
A27: JS2 | B27: Переменные и Функции. Область видимости. | C27: 1 | D27: 10 | E27: JS2 | F27: 1
B28: Объявление и использование переменных
B29: Объявление и использование функций
B30: Область видимости. Что такое «поднятие» (hoisting)
A31: JS3 | B31: DOM/BOM. | C31: 1 | D31: 15 | E31: JS3 | F31: 1
B32: Что такое DOM? Из чего состоит DOM, Узлы и их виды.
B33: Что такое BOM? Что в себя включает BOM?
A34: JS4 | B34: Обработка событий. | C34: 1 | D34: 10 | E34: JS4 | F34: 1
B35: Назначение обработчиков событий. В чем разница каждого способа.
B36: Всплытие, погружение событий.
B37: Объект event и его свойства.
A38: JS5 | B38: Сложные структуры | C38: 1 | D38: 15 | E38: JS5 | F38: 1
B39: String
B40: Numbers
B41: Date
B42: Symbol
...

Sheet .NET
A1: # | B1: Вопросы | C1: Баллы | D1: Длительность (мин) | E1: № старого вопроса | F1: Сложность
B2: Архитектура современных приложений | C2: =SUM(C3:C8) -> 6 | D2: =SUM(D3:D8) -> 30
A3: A1 | B3: Консольные приложения | C3: 1 | D3: 5
A4: A2 | B4: Архитектура клиент-сервер | C4: 3 | D4: 15
B5: Взаимодействие серверов с клиентами
B6: 2х, 3х и многоуровневая архитектура клиент-сервер
B7: Тонкий и толстый клиент
A8: A3 | B8: Web Services | C8: 2 | D8: 10
B9: SOAP
B10: RESTful
B11: Сравнение, преимущества/недостатки
B13: ООП | C13: =SUM(C14,C20) -> 3 | D13: =SUM(D14:D20) -> 30
A14: O1 | B14: Основные понятия | C14: 1 | D14: 10
B15: Инкапсуляция
B16: Наследование
B17: Полиморфизм
B18: Типы взаимоотношений классов (ассоциация, агрегация и композиция, обобщение/расширение (наследование))
B19: Интерфейс, абстрактный класс
A20: O2 | B20: Основные паттерны ООП | C20: 2 | D20: 20
B22: Программирование (.NET) | C22: =SUM(C23:C103) -> 63 | D22: =SUM(D23:D103) -> 550
A23: N1 | B23: Основные понятия и типы данных. Понимание что такое сборка и GAC | C23: 1 | D23: 20 | E23: N1, N10 | F23: 1
B24: Объявление
B25: Области видимости.
B26: Операторы
B27: Логические выражения
B28: Структуры кода
B29: Процедуры, функции, классы (объекты)
B30: extension методы (методы расширения)
A31: N2 | B31: Дополнительные возможности | C31: 1 | D31: 15 | E31: N7 | F31: 1
B32: Лямбды
B33: Custom Attributes
A34: N3 | B34: Коллекции | C34: 1 | D34: 20 | E34: N2 | F34: 1
A35: N4 | B35: Обработка исключений. | C35: 1 | D35: 15 | E35: N3 | F35: 1
A36: N5 | B36: Работа с памятью | C36: 1 | D36: 20 | E36: N6 | F36: 1
B37: Модель памяти.
B38: Сборка мусора.
B39: Понимание интерфейса IDisposable.
B40: Finalize
A41: N6 | B41: Потоки данных | C41: 1 | D41: 15 | E41: N11 | F41: 1
A42: N7 | B42: Многопоточность, асинхронное выполнение | C42: 1 | D42: 20 | E42: N4 | F42: 1
...

Sheet PHP
A1: # | B1: Вопросы | C1: Баллы | D1: Длительность (мин)
B2: Архитектура современных приложений | C2: =SUM(C3:C8) -> 6 | D2: =SUM(D3:D8) -> 30
A3: A1 | B3: Консольные приложения | C3: 1 | D3: 5
A4: A2 | B4: Архитектура клиент-сервер | C4: 3 | D4: 15
B5: Взаимодействие серверов с клиентами
B6: 2х, 3х и многоуровневая архитектура клиент-сервер
B7: Тонкий и толстый клиент
A8: A3 | B8: Web Services | C8: 2 | D8: 10
B9: SOAP
B10: RESTful
B11: Сравнение, преимущества/недостатки
B13: ООП | C13: =SUM(C14,C20) -> 3 | D13: =SUM(D14:D20) -> 30
A14: O1 | B14: Основные понятия | C14: 1 | D14: 10
B15: Инкапсуляция
B16: Наследование
B17: Полиморфизм
B18: Типы взаимоотношений классов (ассоциация, агрегация и композиция, обобщение/расширение (наследование))
B19: Интерфейс, абстрактный класс
A20: O2 | B20: Основные паттерны ООП | C20: 2 | D20: 20
B22: Программирование (PHP) | C22: =SUM(C23:C93) -> 40 | D22: =SUM(D23:D93) -> 330
A23: P1 | B23: Типы данных | C23: 1 | D23: 5
B24: boolean, integer, float, string - скалярные
B25: array, object, callable, iterable - смешанные
B26: resource, null – специальные
A27: P2 | B27: Коллекции | C27: 2 | D27: 20
A28: P3 | B28: Объявление и области видимости переменных | C28: 1 | D28: 5
B29: Объявление переменных
B30: глобальная / локальная
B31: ключевое слово global
B32: $GLOBALS
B33: понятие о суперглобальных переменных
B34: static $var (вне класса)
B35: переменные из внешних источников
B36: константы
A37: P4 | B37: Операторы | C37: 1 | D37: 5
A38: P5 | B38: Структуры управления выполнением | C38: 1 | D38: 5
B39: условные
B40: циклы
B41: альтернативный синтаксис (для шаблонов)
B42: require / include
...

Sheet Python
A1: # | B1: Вопросы | C1: Баллы | D1: Длительность (мин)
B2: Архитектура современных приложений | C2: =SUM(C3:C8) -> 6 | D2: =SUM(D3:D8) -> 30
A3: A1 | B3: Консольные приложения | C3: 1 | D3: 5
A4: A2 | B4: Архитектура клиент-сервер | C4: 3 | D4: 15
B5: Взаимодействие серверов с клиентами
B6: 2х, 3х и многоуровневая архитектура клиент-сервер
B7: Тонкий и толстый клиент
A8: A3 | B8: Web Services | C8: 2 | D8: 10
B9: SOAP
B10: RESTful
B11: Сравнение, преимущества/недостатки
B13: ООП | C13: =SUM(C14,C20) -> 3 | D13: =SUM(D14:D20) -> 30
A14: O1 | B14: Основные понятия | C14: 1 | D14: 10
B15: Инкапсуляция
B16: Наследование
B17: Полиморфизм
B18: Типы взаимоотношений классов (ассоциация, агрегация и композиция, обобщение/расширение (наследование))
B19: Интерфейс, абстрактный класс
A20: O2 | B20: Основные паттерны ООП | C20: 2 | D20: 20
B22: Программирование (Python) | C22: =SUM(C23:C98) -> 40 | D22: =SUM(D23:D98) -> 330
A23: Y1 | B23: Основные понятия и типы данных | C23: 1 | D23: 10
B24: Особенности Python
B25: интерпретируемость
B26: модель памяти (счётчик ссылок, сборщик мусора)
B27: динамическая типизация
B28: PEP 8, PEP 20
A29: Y2 | B29: Коллекции (list, dict, tuple, ...) | C29: 2 | D29: 15
B30: область применения
B31: сложность операций поиска/вставки/удаления элемента
A32: Y3 | B32: Модуль collections | C32: 2 | D32: 15
B33: примеры коллекций и их свойства
B34: область применения
B35: collections.abc
A36: Y4 | B36: ФП | C36: 1 | D36: 10
B37: встроенные функции map/filter/reduce
B38: модуль functools
B39: модуль itertools
A40: Y5 | B40: Итераторы и итерируемые объекты | C40: 1 | D40: 10
B41: что такое итератор
B42: уметь написать пример итерируемого объекта и итератора для него
...

Sheet Salesforce
A1: # | B1: Вопросы | C1: Баллы | D1: Длительность (мин)
B2: Архитектура современных приложений | C2: =SUM(C3:C8) -> 6 | D2: =SUM(D3:D8) -> 30
A3: A1 | B3: Консольные приложения | C3: 1 | D3: 5
A4: A2 | B4: Архитектура клиент-сервер | C4: 3 | D4: 15
B5: Взаимодействие серверов с клиентами
B6: 2х, 3х и многоуровневая архитектура клиент-сервер
B7: Тонкий и толстый клиент
A8: A3 | B8: Web Services | C8: 2 | D8: 10
B9: SOAP
B10: RESTful
B11: Сравнение, преимущества/недостатки
B13: ООП | C13: =SUM(C14,C20) -> 3 | D13: =SUM(D14:D20) -> 30
A14: O1 | B14: Основные понятия | C14: 1 | D14: 10
B15: Инкапсуляция
B16: Наследование
B17: Полиморфизм
B18: Типы взаимоотношений классов (ассоциация, агрегация и композиция, обобщение/расширение (наследование))
B19: Интерфейс, абстрактный класс
A20: O2 | B20: Основные паттерны ООП | C20: 2 | D20: 20
B22: Программирование (Salesforce) | C22: =SUM(C23:C95) -> 40 | D22: =SUM(D23:D95) -> 330
A23: S1 | B23: Salesforce платформа [115 мин] | C23: 1 | D23: 10
B24: Salesforce Platform Basics
B25: Platform Development Basics
A26: S2 | B26: Основные стандартные объекты (standard object) [120 мин] | C26: 1 | D26: 15
B27: Leads & Opportunities
B28: Accounts & Contacts
B29: Campaign Basics
B30: Работа с объектом User
A31: S3 | B31: Собственные объекты (custom object) [45 мин] | C31: 1 | D31: 10
B32: Создание и конфигурирование custom object.
B33: Различия между custom и standard объектами и их настройками.
B34: Data Modeling
A35: S4 | B35: Поля объектов (Fields) [120 мин] | C35: 1 | D35: 10
B36: Стандартные и собственные поля
B37: Типы полей и их различия
B38: Customize a Salesforce Object
A39: S5 | B39: Работа с отчетами и панелями мониторинга (dashboard) [120 мин] | C39: 2 | D39: 15
B40: Report type
B41: Reports & Dashboards
A42: S6 | B42: Генерация и обработка Leads & Cases. | C42: 1 | D42: 5
...

Sheet DevOps
A1: # | B1: Вопросы | C1: Баллы | D1: Длительность (мин)
B2: Архитектура и приложения | C2: =SUM(C3:C8) -> 7 | D2: =SUM(D3:D8) -> 60
A3: A1 | B3: Разработка и жизненный цикл приложений | C3: 2 | D3: 10
A4: A2 | B4: Архитектура клиент-сервер | C4: 3 | D4: 30
B5: Взаимодействие серверов с клиентами
B6: 2х, 3х и многоуровневая архитектура клиент-сервер
B7: Тонкий и толстый клиент
A8: A3 | B8: Консольные и оконные приложения | C8: 2 | D8: 20
B10: Операционые системы и оболочки | C10: =SUM(C11:C16) -> 6 | D10: =SUM(D11:D16) -> 90
A11: O1 | B11: Концепции различных операционных систем (Windows, Linux) | C11: 3 | D11: 40
B12: Общие сведения (модель памяти и процессов)
B13: Права доступа
B14: Файловые системы (кофигурационные файлы, структура папок, создание ссылок, файлы внешних устройств)
B15: Ввод-вывод
A16: O2 | B16: Командные оболочки | C16: 3 | D16: 50
B17: Bash
B18: CMD
B19: PowerShell
B21: Сервера, компоненты и системы | C21: =SUM(C22:C64) -> 39 | D21: =SUM(D22:D64) -> 360
A22: D1 | B22: Сетевые протоколы и безопасность | C22: 3 | D22: 20
B23: HTTP/HTTPS
B24: SSL
B25: IP (TCP/UDP)
A26: D2 | B26: Сервера приложений | C26: 3 | D26: 30
B27: TomCat
B28: WildFly
B29: IIS
A30: D3 | B30: Web-сервера | C30: 3 | D30: 40
B31: Apache
B32: Nginx
A33: D4 | B33: MQ | C33: 3 | D33: 20
B34: RabbitMQ
B35: Apache Kafka
A36: D5 | B36: VCS | C36: 3 | D36: 30
B37: Subversion
B38: GIT
A39: D6 | B39: CI/CD | C39: 3 | D39: 30
B40: Jenkins
B41: Teamcity
B42: Облачные CI/CD (Circle CI, Gitlab pipelines, Azure DevOps, Octopus Deploy)
...
